<?xml version="1.0"?>
<robot xmlns:xacro="http://www.ros.org/wiki/xacro">

<xacro:include filename="inertial_macros.xacro" />

<material name="white">
    <color rgba="1 1 1 1"/>
</material>

<material name="orange">
    <color rgba="1 0.3 0.1 1"/>
</material>

<material name="blue">
    <color rgba="0.2 0.2 1 1"/>
</material>

<material name="black">
    <color rgba="0 0 0 1"/>
</material>
<material name="red">
    <color rgba="1 0 0 1"/>
</material>
  



<link name="base_link">
</link>

<joint name="base_footprint_joint" type="fixed">
    <parent link="base_link"/>
    <child link="base_footprint"/>
    <origin xyz="0 0 0" rpy="0 0 0"/>
</joint>

<link name="base_footprint">
</link>

<joint name="chassis_joint" type="fixed">
    <parent link="base_link"/>
    <child link="chassis"/>
    <origin xyz="0 0 0"/>
</joint>

<link name="chassis">
    <visual>
        <origin xyz="0 0 0.15" rpy="0 0 0"/>
        <geometry>
            <cylinder length="0.322" radius="0.225"/>
        </geometry>
        <material name="white"/>
    </visual>
    <collision>
        <origin xyz="0 0 0.15" rpy="0 0 0"/>
        <geometry>
            <cylinder length="0.322" radius="0.225"/>
        </geometry>
    </collision>
    <xacro:inertial_cylinder mass="0.5" length="0.322" radius="0.225">
        <origin xyz="0 0 0.15" rpy="0 0 0"/>
    </xacro:inertial_cylinder>
</link>

<joint name="left_wheel_joint" type="continuous">
    <parent link="base_link"/>
    <child link="left_wheel"/>
    <origin xyz="0 0.169 0" rpy="-${pi/2} 0 0"/>
    <axis xyz="0 0 1"/>
</joint>

<link name="left_wheel">
    <visual>
        <geometry>
            <cylinder length="0.024" radius="0.068" />
        </geometry>
        <material name="blue"/>
    </visual>
    <collision>
        <geometry>
            <sphere radius="0.068" />
        </geometry>
        <material name="blue"/>
    </collision>
    <gazebo reference="left_wheel">
        <material>Gazebo/Black</material>
        <mu1 value="0.1"/>
        <mu2 value="0.1"/>
    </gazebo>
    <xacro:inertial_cylinder mass="0.1" length="0.024" radius="0.068">
        <origin xyz="0 0 0" rpy="0 0 0"/>
    </xacro:inertial_cylinder>
</link>

<joint name="right_wheel_joint" type="continuous">
    <parent link="base_link"/>
    <child link="right_wheel"/>
    <origin xyz="0 -0.169 0" rpy="${pi/2} 0 0"/>
    <axis xyz="0 0 -1"/>
</joint>

<link name="right_wheel">
    <visual>
        <geometry>
            <cylinder length="0.024" radius="0.068" />
        </geometry>
        <material name="blue"/>
    </visual>
    <collision>
        <geometry>
            <sphere radius="0.068" />
        </geometry>
        <material name="blue"/>
    </collision>
    <gazebo reference="right_wheel">
        <material>Gazebo/Black</material>
        <mu1 value="0.1"/>
        <mu2 value="0.1"/>
    </gazebo>
    <xacro:inertial_cylinder mass="0.1" length="0.024" radius="0.068">
        <origin xyz="0 0 0" rpy="0 0 0"/>
    </xacro:inertial_cylinder>
</link>

<joint name="caster_wheel_joint1" type="fixed">
    <parent link="base_link"/>
    <child link="caster_wheel1"/>
    <origin xyz="-0.15 0 0" rpy="0 0 0"/>
</joint>

<link name="caster_wheel1">
    <visual>
        <geometry>
            <sphere radius="0.068" />
        </geometry>
        <material name="black"/>
    </visual>
    <collision>
        <geometry>
            <sphere radius="0.068" />
        </geometry>
        <material name="black"/>
    </collision>
    <gazebo reference="caster_wheel1">
        <mu1 value="0.001"/>
        <mu2 value="0.001"/>
    </gazebo>
    <xacro:inertial_sphere mass="0.1" radius="0.068">
        <origin xyz="0 0 0" rpy="0 0 0"/>
    </xacro:inertial_sphere>
</link>

<joint name="caster_wheel_joint2" type="fixed">
    <parent link="base_link"/>
    <child link="caster_wheel2"/>
    <origin xyz="0.15 0 0" rpy="0 0 0"/>
</joint>

<link name="caster_wheel2">
    <visual>
        <geometry>
            <sphere radius="0.068" />
        </geometry>
        <material name="black"/>
    </visual>
    <collision>
        <geometry>
            <sphere radius="0.068" />
        </geometry>
        <material name="black"/>
    </collision>
    <gazebo reference="caster_wheel2">
        <mu1 value="0.001"/>
        <mu2 value="0.001"/>
    </gazebo>
    <xacro:inertial_sphere mass="0.1" radius="0.068">
        <origin xyz="0 0 0" rpy="0 0 0"/>
    </xacro:inertial_sphere>
</link>

</robot>

